Workbook

Sheet Assumptions
A1: Transurban Group (ASX: TCL) – Forecast Assumptions & Key Drivers
A2: All figures in A$ millions unless otherwise stated. Fiscal year ends 30 June.
A4: SCENARIO TOGGLES
A5: Toll revenue growth method | B5: Forecast
A6: Other revenue growth method | B6: Forecast
A7: Opex % method | B7: Forecast
A8: D&A % method | B8: Forecast
A9: Cost of debt method | B9: Forecast
A10: Tax rate method | B10: Forecast
A12: Assumption / Driver | B12: Unit | C12: FY21 | D12: FY22 | E12: FY23 | F12: FY24 | G12: FY25 | H12: FY26F | I12: FY27F | J12: FY28F | K12: FY29F | L12: FY30F
A14: REVENUE DRIVERS
A15: Toll revenue growth (input) | B15: % | C15: -0.042 | D15: 0.151 | E15: 0.221 | F15: 0.087 | G15: 0.062 | H15: 0.055 | I15: 0.05 | J15: 0.045 | K15: 0.04 | L15: 0.038
A16: Toll revenue growth (active) | B16: % | C16: =C15 | D16: =D15 | E16: =E15 | F16: =F15 | G16: =G15 | H16: =IF($B$5="3yr Avg",AVERAGE(E15:G15),H15) | I16: =IF($B$5="3yr Avg",AVERAGE(E15:G15),I15) | J16: =IF($B$5="3yr Avg",AVERAGE(E15:G15),J15) | K16: =IF($B$5="3yr Avg",AVERAGE(E15:G15),K15) | L16: =IF($B$5="3yr Avg",AVERAGE(E15:G15),L15)
A17: Other revenue growth (input) | B17: % | C17: 0.02 | D17: -0.025 | E17: 0.068 | F17: -0.018 | G17: 0.104 | H17: 0.03 | I17: 0.03 | J17: 0.03 | K17: 0.03 | L17: 0.03
A18: Other revenue growth (active) | B18: % | C18: =C17 | D18: =D17 | E18: =E17 | F18: =F17 | G18: =G17 | H18: =IF($B$6="3yr Avg",AVERAGE(E17:G17),H17) | I18: =IF($B$6="3yr Avg",AVERAGE(E17:G17),I17) | J18: =IF($B$6="3yr Avg",AVERAGE(E17:G17),J17) | K18: =IF($B$6="3yr Avg",AVERAGE(E17:G17),K17) | L18: =IF($B$6="3yr Avg",AVERAGE(E17:G17),L17)
A20: OPERATING COST DRIVERS
A21: Opex as % of revenue (input) | B21: % | C21: 0.352 | D21: 0.325 | E21: 0.315 | F21: 0.307 | G21: 0.308 | H21: 0.305 | I21: 0.3 | J21: 0.295 | K21: 0.29 | L21: 0.288
A22: Opex as % of revenue (active) | B22: % | C22: =C21 | D22: =D21 | E22: =E21 | F22: =F21 | G22: =G21 | H22: =IF($B$7="3yr Avg",AVERAGE(E21:G21),H21) | I22: =IF($B$7="3yr Avg",AVERAGE(E21:G21),I21) | J22: =IF($B$7="3yr Avg",AVERAGE(E21:G21),J21) | K22: =IF($B$7="3yr Avg",AVERAGE(E21:G21),K21) | L22: =IF($B$7="3yr Avg",AVERAGE(E21:G21),L21)
A23: Employee costs as % of revenue | B23: % | C23: 0.085 | D23: 0.08 | E23: 0.074 | F23: 0.073 | G23: 0.072 | H23: 0.072 | I23: 0.07 | J23: 0.069 | K23: 0.068 | L23: 0.067
A24: Employee costs share of total opex | B24: % | C24: 0.24 | D24: 0.25 | E24: 0.24 | F24: 0.24 | G24: 0.23 | H24: 0.25 | I24: 0.25 | J24: 0.25 | K24: 0.25 | L24: 0.25
A25: Road ops share of total opex | B25: % | C25: 0.34 | D25: 0.33 | E25: 0.33 | F25: 0.32 | G25: 0.31 | H25: 0.33 | I25: 0.33 | J25: 0.33 | K25: 0.33 | L25: 0.33
A27: DEPRECIATION & AMORTISATION
A28: D&A as % of NCA (input) | B28: % | C28: 0.027 | D28: 0.027 | E28: 0.027 | F28: 0.027 | G28: 0.028 | H28: 0.028 | I28: 0.028 | J28: 0.028 | K28: 0.028 | L28: 0.028
A29: D&A as % of NCA (active) | B29: % | C29: =C28 | D29: =D28 | E29: =E28 | F29: =F28 | G29: =G28 | H29: =IF($B$8="3yr Avg",AVERAGE(E28:G28),H28) | I29: =IF($B$8="3yr Avg",AVERAGE(E28:G28),I28) | J29: =IF($B$8="3yr Avg",AVERAGE(E28:G28),J28) | K29: =IF($B$8="3yr Avg",AVERAGE(E28:G28),K28) | L29: =IF($B$8="3yr Avg",AVERAGE(E28:G28),L28)
A30: D&A allocation to PP&E | B30: % | C30: 0.4 | D30: 0.4 | E30: 0.4 | F30: 0.4 | G30: 0.4 | H30: 0.4 | I30: 0.4 | J30: 0.4 | K30: 0.4 | L30: 0.4
A31: D&A allocation to intangibles | B31: % | C31: 0.6 | D31: 0.6 | E31: 0.6 | F31: 0.6 | G31: 0.6 | H31: 0.6 | I31: 0.6 | J31: 0.6 | K31: 0.6 | L31: 0.6
A33: FINANCING ASSUMPTIONS
A34: Average cost of debt (input) | B34: % | C34: 0.046 | D34: 0.04 | E34: 0.042 | F34: 0.045 | G34: 0.046 | H34: 0.047 | I34: 0.047 | J34: 0.048 | K34: 0.048 | L34: 0.048
A35: Average cost of debt (active) | B35: % | C35: =C34 | D35: =D34 | E35: =E34 | F35: =F34 | G35: =G34 | H35: =IF($B$9="3yr Avg",AVERAGE(E34:G34),H34) | I35: =IF($B$9="3yr Avg",AVERAGE(E34:G34),I34) | J35: =IF($B$9="3yr Avg",AVERAGE(E34:G34),J34) | K35: =IF($B$9="3yr Avg",AVERAGE(E34:G34),K34) | L35: =IF($B$9="3yr Avg",AVERAGE(E34:G34),L34)
A36: Effective tax rate (input) | B36: % | C36: -0.015 | D36: 0.14 | E36: 0.143 | F36: 0.144 | G36: 0.15 | H36: 0.15 | I36: 0.15 | J36: 0.15 | K36: 0.15 | L36: 0.15
A37: Effective tax rate (active) | B37: % | C37: =C36 | D37: =D36 | E37: =E36 | F37: =F36 | G37: =G36 | H37: =IF($B$10="3yr Avg",AVERAGE(E36:G36),H36) | I37: =IF($B$10="3yr Avg",AVERAGE(E36:G36),I36) | J37: =IF($B$10="3yr Avg",AVERAGE(E36:G36),J36) | K37: =IF($B$10="3yr Avg",AVERAGE(E36:G36),K36) | L37: =IF($B$10="3yr Avg",AVERAGE(E36:G36),L36)
A38: Statutory tax rate | B38: % | C38: 0.3 | D38: 0.3 | E38: 0.3 | F38: 0.3 | G38: 0.3 | H38: 0.3 | I38: 0.3 | J38: 0.3 | K38: 0.3 | L38: 0.3
A39: Current borrowings as % of total debt | B39: % | C39: 0.06 | D39: 0.055 | E39: 0.055 | F39: 0.05 | G39: 0.05 | H39: 0.05 | I39: 0.05 | J39: 0.05 | K39: 0.05 | L39: 0.05
A40: DRP / dilution rate | B40: % | C40: 0.01 | D40: 0.01 | E40: 0.01 | F40: 0.01 | G40: 0.01 | H40: 0.01 | I40: 0.01 | J40: 0.01 | K40: 0.01 | L40: 0.01
A42: BALANCE SHEET DRIVERS
A43: Capex (maintenance + growth) | B43: A$m | C43: 628 | D43: 1092 | E43: 1805 | F43: 1420 | G43: 1200 | H43: 1300 | I43: 1350 | J43: 1400 | K43: 1250 | L43: 1200
A44: Trade receivables days | B44: days | C44: 28 | D44: 26 | E44: 25 | F44: 24 | G44: 24 | H44: 24 | I44: 24 | J44: 24 | K44: 24 | L44: 24
A45: Trade payables days | B45: days | C45: 55 | D45: 52 | E45: 50 | F45: 48 | G45: 48 | H45: 48 | I45: 48 | J45: 48 | K45: 48 | L45: 48
A46: Other current assets growth rate | B46: % | C46: 0.03 | D46: 0.03 | E46: 0.03 | F46: 0.03 | G46: 0.03 | H46: 0.03 | I46: 0.03 | J46: 0.03 | K46: 0.03 | L46: 0.03
A47: JV investments growth rate | B47: % | C47: -0.02 | D47: -0.02 | E47: -0.02 | F47: -0.02 | G47: -0.02 | H47: -0.02 | I47: -0.02 | J47: -0.02 | K47: -0.02 | L47: -0.02
...

Sheet Income Statement
A1: Transurban Group – Income Statement
A2: A$ millions | Fiscal year ends 30 June
A4: Income Statement | C4: FY21 | D4: FY22 | E4: FY23 | F4: FY24 | G4: FY25 | H4: FY26F | I4: FY27F | J4: FY28F | K4: FY29F | L4: FY30F
A5: Revenue
A6: Toll revenue | B6: A$m | C6: 2459 | D6: 2830 | E6: 3455 | F6: 3756 | G6: 3990 | H6: =G6*(1+Assumptions!H16) | I6: =H6*(1+Assumptions!I16) | J6: =I6*(1+Assumptions!J16) | K6: =J6*(1+Assumptions!K16) | L6: =K6*(1+Assumptions!L16)
A7: Other revenue | B7: A$m | C7: 319 | D7: 311 | E7: 332 | F7: 326 | G7: 360 | H7: =G7*(1+Assumptions!H18) | I7: =H7*(1+Assumptions!I18) | J7: =I7*(1+Assumptions!J18) | K7: =J7*(1+Assumptions!K18) | L7: =K7*(1+Assumptions!L18)
A8: Total Revenue | B8: A$m | C8: 2778 | D8: 3141 | E8: 3787 | F8: 4082 | G8: 4350 | H8: =H6+H7 | I8: =I6+I7 | J8: =J6+J7 | K8: =K6+K7 | L8: =L6+L7
A10: Operating Expenses
A11: Employee costs | B11: A$m | C11: -236 | D11: -251 | E11: -280 | F11: -298 | G11: -313 | H11: =-H8*Assumptions!H22*Assumptions!H24 | I11: =-I8*Assumptions!I22*Assumptions!I24 | J11: =-J8*Assumptions!J22*Assumptions!J24 | K11: =-K8*Assumptions!K22*Assumptions!K24 | L11: =-L8*Assumptions!L22*Assumptions!L24
A12: Road operating costs | B12: A$m | C12: -340 | D12: -333 | E12: -380 | F12: -395 | G12: -418 | H12: =-H8*Assumptions!H22*Assumptions!H25 | I12: =-I8*Assumptions!I22*Assumptions!I25 | J12: =-J8*Assumptions!J22*Assumptions!J25 | K12: =-K8*Assumptions!K22*Assumptions!K25 | L12: =-L8*Assumptions!L22*Assumptions!L25
A13: Corporate & admin costs | B13: A$m | C13: -401 | D13: -436 | E13: -535 | F13: -562 | G13: -608 | H13: =-H8*Assumptions!H22-H11-H12 | I13: =-I8*Assumptions!I22-I11-I12 | J13: =-J8*Assumptions!J22-J11-J12 | K13: =-K8*Assumptions!K22-K11-K12 | L13: =-L8*Assumptions!L22-L11-L12
A14: Total Operating Expenses | B14: A$m | C14: -977 | D14: -1020 | E14: -1195 | F14: -1255 | G14: -1339 | H14: =H11+H12+H13 | I14: =I11+I12+I13 | J14: =J11+J12+J13 | K14: =K11+K12+K13 | L14: =L11+L12+L13
A16: EBITDA | B16: A$m | C16: 1801 | D16: 2121 | E16: 2592 | F16: 2827 | G16: 3011 | H16: =H8+H14 | I16: =I8+I14 | J16: =J8+J14 | K16: =K8+K14 | L16: =L8+L14
A17: Depreciation & amortisation | B17: A$m | C17: -856 | D17: -880 | E17: -905 | F17: -930 | G17: -958 | H17: =-'Balance Sheet'!G17*Assumptions!H29 | I17: =-'Balance Sheet'!H17*Assumptions!I29 | J17: =-'Balance Sheet'!I17*Assumptions!J29 | K17: =-'Balance Sheet'!J17*Assumptions!K29 | L17: =-'Balance Sheet'!K17*Assumptions!L29
A18: EBIT | B18: A$m | C18: 945 | D18: 1241 | E18: 1687 | F18: 1897 | G18: 2053 | H18: =H16+H17 | I18: =I16+I17 | J18: =J16+J17 | K18: =K16+K17 | L18: =L16+L17
A20: Net finance costs | B20: A$m | C20: -907 | D20: -821 | E20: -963 | F20: -1093 | G20: -1150 | H20: =-'Balance Sheet'!G32*Assumptions!H35 | I20: =-'Balance Sheet'!H32*Assumptions!I35 | J20: =-'Balance Sheet'!I32*Assumptions!J35 | K20: =-'Balance Sheet'!J32*Assumptions!K35 | L20: =-'Balance Sheet'!K32*Assumptions!L35
A21: Profit / (Loss) before tax | B21: A$m | C21: 38 | D21: 420 | E21: 724 | F21: 804 | G21: 903 | H21: =H18+H20 | I21: =I18+I20 | J21: =J18+J20 | K21: =K18+K20 | L21: =L18+L20
A22: Income tax (expense) / benefit | B22: A$m | C22: 7 | D22: -141 | E22: -270 | F22: -249 | G22: -282 | H22: =-H21*Assumptions!H37 | I22: =-I21*Assumptions!I37 | J22: =-J21*Assumptions!J37 | K22: =-K21*Assumptions!K37 | L22: =-L21*Assumptions!L37
A23: Net Profit / (Loss) After Tax | B23: A$m | C23: 45 | D23: 279 | E23: 454 | F23: 555 | G23: 621 | H23: =H21+H22 | I23: =I21+I22 | J23: =J21+J22 | K23: =K21+K22 | L23: =L21+L22

Sheet Balance Sheet
A1: Transurban Group – Balance Sheet
A2: A$ millions | As at 30 June
A4: Balance Sheet | C4: FY21 | D4: FY22 | E4: FY23 | F4: FY24 | G4: FY25 | H4: FY26F | I4: FY27F | J4: FY28F | K4: FY29F | L4: FY30F
A5: ASSETS
A6: Current Assets
A7: Cash & cash equivalents | B7: A$m | C7: 2548 | D7: 3145 | E7: 2780 | F7: 2350 | G7: 2520 | H7: ='Cash Flow Statement'!H26 | I7: ='Cash Flow Statement'!I26 | J7: ='Cash Flow Statement'!J26 | K7: ='Cash Flow Statement'!K26 | L7: ='Cash Flow Statement'!L26
A8: Trade & other receivables | B8: A$m | C8: 213 | D8: 224 | E8: 260 | F8: 269 | G8: 286 | H8: ='Income Statement'!H8/365*Assumptions!H44 | I8: ='Income Statement'!I8/365*Assumptions!I44 | J8: ='Income Statement'!J8/365*Assumptions!J44 | K8: ='Income Statement'!K8/365*Assumptions!K44 | L8: ='Income Statement'!L8/365*Assumptions!L44
A9: Other current assets | B9: A$m | C9: 195 | D9: 210 | E9: 225 | F9: 230 | G9: 240 | H9: =G9*(1+Assumptions!H46) | I9: =H9*(1+Assumptions!I46) | J9: =I9*(1+Assumptions!J46) | K9: =J9*(1+Assumptions!K46) | L9: =K9*(1+Assumptions!L46)
A10: Total Current Assets | B10: A$m | C10: 2956 | D10: 3579 | E10: 3265 | F10: 2849 | G10: 3046 | H10: =H7+H8+H9 | I10: =I7+I8+I9 | J10: =J7+J8+J9 | K10: =K7+K8+K9 | L10: =L7+L8+L9
A12: Non-Current Assets
A13: Property, plant & equipment | B13: A$m | C13: 6125 | D13: 6850 | E13: 7900 | F13: 8100 | G13: 8050 | H13: =G13+Assumptions!H43+'Income Statement'!H17*Assumptions!H30 | I13: =H13+Assumptions!I43+'Income Statement'!I17*Assumptions!I30 | J13: =I13+Assumptions!J43+'Income Statement'!J17*Assumptions!J30 | K13: =J13+Assumptions!K43+'Income Statement'!K17*Assumptions!K30 | L13: =K13+Assumptions!L43+'Income Statement'!L17*Assumptions!L30
A14: Intangible assets (concessions) | B14: A$m | C14: 22450 | D14: 23100 | E14: 24200 | F14: 24650 | G14: 24800 | H14: =G14+'Income Statement'!H17*Assumptions!H31 | I14: =H14+'Income Statement'!I17*Assumptions!I31 | J14: =I14+'Income Statement'!J17*Assumptions!J31 | K14: =J14+'Income Statement'!K17*Assumptions!K31 | L14: =K14+'Income Statement'!L17*Assumptions!L31
A15: Investments in joint ventures | B15: A$m | C15: 1820 | D15: 1750 | E15: 1680 | F15: 1620 | G15: 1580 | H15: =G15*(1+Assumptions!H47) | I15: =H15*(1+Assumptions!I47) | J15: =I15*(1+Assumptions!J47) | K15: =J15*(1+Assumptions!K47) | L15: =K15*(1+Assumptions!L47)
A16: Other non-current assets | B16: A$m | C16: 1250 | D16: 1380 | E16: 1520 | F16: 1580 | G16: 1620 | H16: =G16*(1+Assumptions!H48) | I16: =H16*(1+Assumptions!I48) | J16: =I16*(1+Assumptions!J48) | K16: =J16*(1+Assumptions!K48) | L16: =K16*(1+Assumptions!L48)
A17: Total Non-Current Assets | B17: A$m | C17: 31645 | D17: 33080 | E17: 35300 | F17: 35950 | G17: 36050 | H17: =H13+H14+H15+H16 | I17: =I13+I14+I15+I16 | J17: =J13+J14+J15+J16 | K17: =K13+K14+K15+K16 | L17: =L13+L14+L15+L16
A19: Total Assets | B19: A$m | C19: 34601 | D19: 36659 | E19: 38565 | F19: 38799 | G19: 39096 | H19: =H10+H17 | I19: =I10+I17 | J19: =J10+J17 | K19: =K10+K17 | L19: =L10+L17
A21: LIABILITIES
A22: Current Liabilities
A23: Trade & other payables | B23: A$m | C23: 485 | D23: 510 | E23: 555 | F23: 530 | G23: 550 | H23: =-'Income Statement'!H14/365*Assumptions!H45 | I23: =-'Income Statement'!I14/365*Assumptions!I45 | J23: =-'Income Statement'!J14/365*Assumptions!J45 | K23: =-'Income Statement'!K14/365*Assumptions!K45 | L23: =-'Income Statement'!L14/365*Assumptions!L45
A24: Current borrowings | B24: A$m | C24: 1250 | D24: 1400 | E24: 1600 | F24: 1300 | G24: 1200 | H24: =(G32+Assumptions!H55)*Assumptions!H39 | I24: =(H32+Assumptions!I55)*Assumptions!I39 | J24: =(I32+Assumptions!J55)*Assumptions!J39 | K24: =(J32+Assumptions!K55)*Assumptions!K39 | L24: =(K32+Assumptions!L55)*Assumptions!L39
A25: Other current liabilities | B25: A$m | C25: 580 | D25: 620 | E25: 680 | F25: 710 | G25: 740 | H25: =G25*(1+Assumptions!H49) | I25: =H25*(1+Assumptions!I49) | J25: =I25*(1+Assumptions!J49) | K25: =J25*(1+Assumptions!K49) | L25: =K25*(1+Assumptions!L49)
A26: Total Current Liabilities | B26: A$m | C26: 2315 | D26: 2530 | E26: 2835 | F26: 2540 | G26: 2490 | H26: =H23+H24+H25 | I26: =I23+I24+I25 | J26: =J23+J24+J25 | K26: =K23+K24+K25 | L26: =L23+L24+L25
A28: Non-Current Liabilities
A29: Non-current borrowings | B29: A$m | C29: 19580 | D29: 21230 | E29: 23430 | F29: 23730 | G29: 23830 | H29: =G32+Assumptions!H55-H24 | I29: =H32+Assumptions!I55-I24 | J29: =I32+Assumptions!J55-J24 | K29: =J32+Assumptions!K55-K24 | L29: =K32+Assumptions!L55-L24
A30: Other non-current liabilities | B30: A$m | C30: 2350 | D30: 2480 | E30: 2620 | F30: 2700 | G30: 2780 | H30: =G30*(1+Assumptions!H50) | I30: =H30*(1+Assumptions!I50) | J30: =I30*(1+Assumptions!J50) | K30: =J30*(1+Assumptions!K50) | L30: =K30*(1+Assumptions!L50)
A31: Total Non-Current Liabilities | B31: A$m | C31: 21930 | D31: 23710 | E31: 26050 | F31: 26430 | G31: 26610 | H31: =H29+H30 | I31: =I29+I30 | J31: =J29+J30 | K31: =K29+K30 | L31: =L29+L30
A32: Total Borrowings (current + non-current) | B32: A$m | C32: 20830 | D32: 22630 | E32: 25030 | F32: 25030 | G32: 25030 | H32: =H24+H29 | I32: =I24+I29 | J32: =J24+J29 | K32: =K24+K29 | L32: =L24+L29
A34: Total Liabilities | B34: A$m | C34: 24245 | D34: 26240 | E34: 28885 | F34: 28970 | G34: 29100 | H34: =H26+H31 | I34: =I26+I31 | J34: =J26+J31 | K34: =K26+K31 | L34: =L26+L31
A36: EQUITY
A37: Share capital | B37: A$m | C37: 13845 | D37: 14250 | E37: 14680 | F37: 15020 | G37: 15310 | H37: =G37*(1+Assumptions!H40) | I37: =H37*(1+Assumptions!I40) | J37: =I37*(1+Assumptions!J40) | K37: =J37*(1+Assumptions!K40) | L37: =K37*(1+Assumptions!L40)
A38: Retained earnings / (losses) | B38: A$m | C38: -3847 | D38: -4211 | E38: -5380 | F38: -5591 | G38: -5726 | H38: =G38+'Income Statement'!H23-Assumptions!H53*Assumptions!H54/100 | I38: =H38+'Income Statement'!I23-Assumptions!I53*Assumptions!I54/100 | J38: =I38+'Income Statement'!J23-Assumptions!J53*Assumptions!J54/100 | K38: =J38+'Income Statement'!K23-Assumptions!K53*Assumptions!K54/100 | L38: =K38+'Income Statement'!L23-Assumptions!L53*Assumptions!L54/100
A39: Reserves | B39: A$m | C39: 358 | D39: 380 | E39: 380 | F39: 400 | G39: 412 | H39: =G39 | I39: =H39 | J39: =I39 | K39: =J39 | L39: =K39
A40: Total Equity | B40: A$m | C40: 10356 | D40: 10419 | E40: 9680 | F40: 9829 | G40: 9996 | H40: =H37+H38+H39 | I40: =I37+I38+I39 | J40: =J37+J38+J39 | K40: =K37+K38+K39 | L40: =L37+L38+L39
A42: Total Liabilities & Equity | B42: A$m | C42: 34601 | D42: 36659 | E42: 38565 | F42: 38799 | G42: 39096 | H42: =H34+H40 | I42: =I34+I40 | J42: =J34+J40 | K42: =K34+K40 | L42: =L34+L40
A44: Balance Sheet Check (Assets - L&E) | B44: A$m | C44: =C19-C42 | D44: =D19-D42 | E44: =E19-E42 | F44: =F19-F42 | G44: =G19-G42 | H44: =H19-H42 | I44: =I19-I42 | J44: =J19-J42 | ... L44: =L19-L42

Sheet Cash Flow Statement
A1: Transurban Group – Cash Flow Statement
A2: A$ millions | Fiscal year ends 30 June
A4: Cash Flow Statement | C4: FY21 | D4: FY22 | E4: FY23 | F4: FY24 | G4: FY25 | H4: FY26F | I4: FY27F | J4: FY28F | K4: FY29F | L4: FY30F
A5: OPERATING ACTIVITIES
A6: Net profit / (loss) after tax | B6: A$m | C6: 45 | D6: 279 | E6: 454 | F6: 555 | G6: 621 | H6: ='Income Statement'!H23 | I6: ='Income Statement'!I23 | J6: ='Income Statement'!J23 | K6: ='Income Statement'!K23 | L6: ='Income Statement'!L23
A7: Add back: D&A | B7: A$m | C7: 856 | D7: 880 | E7: 905 | F7: 930 | G7: 958 | H7: =-'Income Statement'!H17 | I7: =-'Income Statement'!I17 | J7: =-'Income Statement'!J17 | K7: =-'Income Statement'!K17 | L7: =-'Income Statement'!L17
A8: Changes in working capital | B8: A$m | C8: -45 | D8: 30 | E8: -60 | F8: 25 | G8: -15 | H8: =-('Balance Sheet'!H8-'Balance Sheet'!G8)+('Balance Sheet'!H23-'Balance Sheet'!G23) | I8: =-('Balance Sheet'!I8-'Balance Sheet'!H8)+('Balance Sheet'!I23-'Balance Sheet'!H23) | J8: =-('Balance Sheet'!J8-'Balance Sheet'!I8)+('Balance Sheet'!J23-'Balance Sheet'!I23) | K8: =-('Balance Sheet'!K8-'Balance Sheet'!J8)+('Balance Sheet'!K23-'Balance Sheet'!J23) | L8: =-('Balance Sheet'!L8-'Balance Sheet'!K8)+('Balance Sheet'!L23-'Balance Sheet'!K23)
A9: Other operating adjustments | B9: A$m | C9: 120 | D9: 135 | E9: 150 | F9: 160 | G9: 170 | H9: =G9*(1+Assumptions!H56) | I9: =H9*(1+Assumptions!I56) | J9: =I9*(1+Assumptions!J56) | K9: =J9*(1+Assumptions!K56) | L9: =K9*(1+Assumptions!L56)
A10: Net Cash from Operating Activities | B10: A$m | C10: 976 | D10: 1324 | E10: 1449 | F10: 1670 | G10: 1734 | H10: =H6+H7+H8+H9 | I10: =I6+I7+I8+I9 | J10: =J6+J7+J8+J9 | K10: =K6+K7+K8+K9 | L10: =L6+L7+L8+L9
A12: INVESTING ACTIVITIES
A13: Capital expenditure | B13: A$m | C13: -628 | D13: -1092 | E13: -1805 | F13: -1420 | G13: -1200 | H13: =-Assumptions!H43 | I13: =-Assumptions!I43 | J13: =-Assumptions!J43 | K13: =-Assumptions!K43 | L13: =-Assumptions!L43
A14: Other investing activities | B14: A$m | C14: -150 | D14: -80 | E14: -120 | F14: -100 | G14: -90 | H14: =G14 | I14: =H14 | J14: =I14 | K14: =J14 | L14: =K14
A15: Net Cash from Investing Activities | B15: A$m | C15: -778 | D15: -1172 | E15: -1925 | F15: -1520 | G15: -1290 | H15: =H13+H14 | I15: =I13+I14 | J15: =J13+J14 | K15: =K13+K14 | L15: =L13+L14
A17: FINANCING ACTIVITIES
A18: Proceeds from / (repayment of) borrowings | B18: A$m | C18: 1200 | D18: 2050 | E18: 2800 | F18: 600 | G18: 300 | H18: =Assumptions!H55 | I18: =Assumptions!I55 | J18: =Assumptions!J55 | K18: =Assumptions!K55 | L18: =Assumptions!L55
A19: Dividends / distributions paid | B19: A$m | C19: -792 | D19: -1032 | E19: -1218 | F19: -1276 | G19: -1313 | H19: =-Assumptions!H53*Assumptions!H54/100 | I19: =-Assumptions!I53*Assumptions!I54/100 | J19: =-Assumptions!J53*Assumptions!J54/100 | K19: =-Assumptions!K53*Assumptions!K54/100 | L19: =-Assumptions!L53*Assumptions!L54/100
A20: Equity issuance (DRP & placements) | B20: A$m | C20: 405 | D20: 450 | E20: 430 | F20: 340 | G20: 290 | H20: ='Balance Sheet'!G37*Assumptions!H57 | I20: ='Balance Sheet'!H37*Assumptions!I57 | J20: ='Balance Sheet'!I37*Assumptions!J57 | K20: ='Balance Sheet'!J37*Assumptions!K57 | L20: ='Balance Sheet'!K37*Assumptions!L57
A21: Net Cash from Financing Activities | B21: A$m | C21: 813 | D21: 1468 | E21: 2012 | F21: -336 | G21: -723 | H21: =H18+H19+H20 | I21: =I18+I19+I20 | J21: =J18+J19+J20 | K21: =K18+K19+K20 | L21: =L18+L19+L20
A23: Net increase / (decrease) in cash | B23: A$m | C23: 1011 | D23: 1620 | E23: 1536 | F23: -186 | G23: -279 | H23: =H10+H15+H21 | I23: =I10+I15+I21 | J23: =J10+J15+J21 | K23: =K10+K15+K21 | L23: =L10+L15+L21
A24: FX & other adjustments | B24: A$m | C24: -748 | D24: -1023 | E24: -1901 | F24: -244 | G24: 449 | H24: 0 | I24: 0 | J24: 0 | K24: 0 | L24: 0
A25: Opening cash balance | B25: A$m | C25: 2285 | D25: 2548 | E25: 3145 | F25: 2780 | G25: 2350 | H25: ='Balance Sheet'!G7 | I25: ='Balance Sheet'!H7 | J25: ='Balance Sheet'!I7 | K25: ='Balance Sheet'!J7 | L25: ='Balance Sheet'!K7
A26: Closing Cash Balance | B26: A$m | C26: 2548 | D26: 3145 | E26: 2780 | F26: 2350 | G26: 2520 | H26: =H25+H23+H24 | I26: =I25+I23+I24 | J26: =J25+J23+J24 | K26: =K25+K23+K24 | L26: =L25+L23+L24

Sheet Notes
A1: Transurban Group – Notes to the Financial Statements
A2: A$ millions | Fiscal year ends 30 June
A4: Notes | C4: FY21 | D4: FY22 | E4: FY23 | F4: FY24 | G4: FY25 | H4: FY26F | I4: FY27F | J4: FY28F | K4: FY29F | L4: FY30F
A5: REVENUE BREAKDOWN
A6: Toll revenue | B6: A$m | C6: ='Income Statement'!C6 | D6: ='Income Statement'!D6 | E6: ='Income Statement'!E6 | F6: ='Income Statement'!F6 | G6: ='Income Statement'!G6 | H6: ='Income Statement'!H6 | I6: ='Income Statement'!I6 | J6: ='Income Statement'!J6 | ... L6: ='Income Statement'!L6
A7: Construction revenue | B7: A$m | C7: 180 | D7: 320 | E7: 540 | F7: 420 | G7: 350 | H7: =G7*(1+Assumptions!H60) | I7: =H7*(1+Assumptions!I60) | J7: =I7*(1+Assumptions!J60) | K7: =J7*(1+Assumptions!K60) | L7: =K7*(1+Assumptions!L60)
A8: Other revenue | B8: A$m | C8: ='Income Statement'!C7 | D8: ='Income Statement'!D7 | E8: ='Income Statement'!E7 | F8: ='Income Statement'!F7 | G8: ='Income Statement'!G7 | H8: ='Income Statement'!H7 | I8: ='Income Statement'!I7 | J8: ='Income Statement'!J7 | ... L8: ='Income Statement'!L7
A9: Total Revenue | B9: A$m | C9: ='Income Statement'!C8 | D9: ='Income Statement'!D8 | E9: ='Income Statement'!E8 | F9: ='Income Statement'!F8 | G9: ='Income Statement'!G8 | H9: ='Income Statement'!H8 | I9: ='Income Statement'!I8 | J9: ='Income Statement'!J8 | ... L9: ='Income Statement'!L8
A11: SEGMENT REPORTING
A12: Melbourne (CityLink)
A13: Revenue | B13: A$m | C13: 820 | D13: 920 | E13: 1080 | F13: 1150 | G13: 1220
A14: EBITDA | B14: A$m | C14: 620 | D14: 710 | E14: 840 | F14: 900 | G14: 960
A15: Sydney
A16: Revenue | B16: A$m | C16: 1050 | D16: 1220 | E16: 1520 | F16: 1680 | G16: 1800
A17: EBITDA | B17: A$m | C17: 750 | D17: 890 | E17: 1120 | F17: 1250 | G17: 1350
A18: Brisbane
A19: Revenue | B19: A$m | C19: 430 | D19: 480 | E19: 560 | F19: 600 | G19: 640
A20: EBITDA | B20: A$m | C20: 310 | D20: 350 | E20: 410 | F20: 440 | G20: 470
A21: North America
A22: Revenue | B22: A$m | C22: 478 | D22: 521 | E22: 627 | F22: 652 | G22: 690
A23: EBITDA | B23: A$m | C23: 120 | D23: 150 | E23: 205 | F23: 230 | G23: 260
A24: Total segment revenue | B24: A$m | C24: =C13+C16+C19+C22 | D24: =D13+D16+D19+D22 | E24: =E13+E16+E19+E22 | F24: =F13+F16+F19+F22 | G24: =G13+G16+G19+G22
A25: Total segment EBITDA | B25: A$m | C25: =C14+C17+C20+C23 | D25: =D14+D17+D20+D23 | E25: =E14+E17+E20+E23 | F25: =F14+F17+F20+F23 | G25: =G14+G17+G20+G23
A26: Reconciliation to IS EBITDA | B26: A$m | C26: ='Income Statement'!C16 | D26: ='Income Statement'!D16 | E26: ='Income Statement'!E16 | F26: ='Income Statement'!F16 | G26: ='Income Statement'!G16
A28: INTANGIBLE ASSETS (CONCESSION RIGHTS)
A29: Opening balance | B29: A$m | C29: 22100 | D29: =C32 | E29: =D32 | F29: =E32 | G29: =F32 | H29: =G32 | I29: =H32 | J29: =I32 | K29: =J32 | L29: =K32
A30: Additions (capitalised construction) | B30: A$m | C30: 530 | D30: 680 | E30: 1150 | F30: 880 | G30: 720 | H30: =H7 | I30: =I7 | J30: =J7 | K30: =K7 | L30: =L7
A31: Amortisation charge | B31: A$m | C31: ='Income Statement'!C17*Assumptions!C31 | D31: ='Income Statement'!D17*Assumptions!D31 | E31: ='Income Statement'!E17*Assumptions!E31 | F31: ='Income Statement'!F17*Assumptions!F31 | G31: ='Income Statement'!G17*Assumptions!G31 | H31: ='Income Statement'!H17*Assumptions!H31 | I31: ='Income Statement'!I17*Assumptions!I31 | J31: ='Income Statement'!J17*Assumptions!J31 | ... L31: ='Income Statement'!L17*Assumptions!L31
A32: Closing balance | B32: A$m | C32: =C29+C30+C31 | D32: =D29+D30+D31 | E32: =E29+E30+E31 | F32: =F29+F30+F31 | G32: =G29+G30+G31 | H32: =H29+H30+H31 | I32: =I29+I30+I31 | J32: =J29+J30+J31 | ... L32: =L29+L30+L31
A33: Cross-check to BS | B33: A$m | C33: ='Balance Sheet'!C14 | D33: ='Balance Sheet'!D14 | E33: ='Balance Sheet'!E14 | F33: ='Balance Sheet'!F14 | G33: ='Balance Sheet'!G14 | H33: ='Balance Sheet'!H14 | I33: ='Balance Sheet'!I14 | J33: ='Balance Sheet'!J14 | ... L33: ='Balance Sheet'!L14
A35: BORROWINGS
A36: Current borrowings | B36: A$m | C36: ='Balance Sheet'!C24 | D36: ='Balance Sheet'!D24 | E36: ='Balance Sheet'!E24 | F36: ='Balance Sheet'!F24 | G36: ='Balance Sheet'!G24 | H36: ='Balance Sheet'!H24 | I36: ='Balance Sheet'!I24 | J36: ='Balance Sheet'!J24 | ... L36: ='Balance Sheet'!L24
A37: Non-current borrowings | B37: A$m | C37: ='Balance Sheet'!C29 | D37: ='Balance Sheet'!D29 | E37: ='Balance Sheet'!E29 | F37: ='Balance Sheet'!F29 | G37: ='Balance Sheet'!G29 | H37: ='Balance Sheet'!H29 | I37: ='Balance Sheet'!I29 | J37: ='Balance Sheet'!J29 | ... L37: ='Balance Sheet'!L29
A38: Total borrowings | B38: A$m | C38: ='Balance Sheet'!C32 | D38: ='Balance Sheet'!D32 | E38: ='Balance Sheet'!E32 | F38: ='Balance Sheet'!F32 | G38: ='Balance Sheet'!G32 | H38: ='Balance Sheet'!H32 | I38: ='Balance Sheet'!I32 | J38: ='Balance Sheet'!J32 | ... L38: ='Balance Sheet'!L32
A40: Maturity Profile
A41: Within 1 year | B41: A$m | C41: =C36 | D41: =D36 | E41: =E36 | F41: =F36 | G41: =G36 | H41: =H36 | I41: =I36 | J41: =J36 | ... L41: =L36
A42: 1-2 years | B42: A$m | C42: 1100 | D42: 1250 | E42: 1400 | F42: 1150 | G42: 1050 | H42: =H38*Assumptions!H61 | I42: =I38*Assumptions!I61 | J42: =J38*Assumptions!J61 | K42: =K38*Assumptions!K61 | L42: =L38*Assumptions!L61
A43: 2-5 years | B43: A$m | C43: 5200 | D43: 5650 | E43: 6300 | F43: 6400 | G43: 6500 | H43: =H38*Assumptions!H62 | I43: =I38*Assumptions!I62 | J43: =J38*Assumptions!J62 | K43: =K38*Assumptions!K62 | L43: =L38*Assumptions!L62
A44: Over 5 years | B44: A$m | C44: =C38-C41-C42-C43 | D44: =D38-D41-D42-D43 | E44: =E38-E41-E42-E43 | F44: =F38-F41-F42-F43 | G44: =G38-G41-G42-G43 | H44: =H38-H41-H42-H43 | I44: =I38-I41-I42-I43 | J44: =J38-J41-J42-J43 | ... L44: =L38-L41-L42-L43
A45: Total (maturity check) | B45: A$m | C45: =C41+C42+C43+C44 | D45: =D41+D42+D43+D44 | E45: =E41+E42+E43+E44 | F45: =F41+F42+F43+F44 | G45: =G41+G42+G43+G44 | H45: =H41+H42+H43+H44 | I45: =I41+I42+I43+I44 | J45: =J41+J42+J43+J44 | ... L45: =L41+L42+L43+L44
...
